Workbook

Sheet Лист1
A1: ID операции | B1: Дата | C1: ID магазина | D1: Артикул | E1: Количество упаковок, шт. | F1: Тип операции | G1: Цена товара | H1: Район | J1: 12434130
A2: 1081 | B2: 45084 | C2: M1 | D2: 1 | E2: 180 | F2: Продажа | G2: 110 | H2: Центральный | J2: =E2*G2 -> 19800
A3: 1101 | B3: 45084 | C3: M1 | D3: 21 | E3: 199 | F3: Продажа | G3: 110 | H3: Центральный | J3: =E3*G3 -> 21890
A4: 1117 | B4: 45084 | C4: M5 | D4: 1 | E4: 192 | F4: Продажа | G4: 110 | H4: Центральный | J4: =E4*G4 -> 21120
A5: 1137 | B5: 45084 | C5: M5 | D5: 21 | E5: 158 | F5: Продажа | G5: 110 | H5: Центральный | J5: =E5*G5 -> 17380
A6: 1153 | B6: 45084 | C6: M6 | D6: 1 | E6: 155 | F6: Продажа | G6: 110 | H6: Центральный | J6: =E6*G6 -> 17050
A7: 1173 | B7: 45084 | C7: M6 | D7: 21 | E7: 146 | F7: Продажа | G7: 110 | H7: Центральный | J7: =E7*G7 -> 16060
A8: 1189 | B8: 45084 | C8: M10 | D8: 1 | E8: 122 | F8: Продажа | G8: 110 | H8: Центральный | J8: =E8*G8 -> 13420
A9: 1209 | B9: 45084 | C9: M10 | D9: 21 | E9: 105 | F9: Продажа | G9: 110 | H9: Центральный | J9: =E9*G9 -> 11550
A10: 1225 | B10: 45084 | C10: M15 | D10: 1 | E10: 144 | F10: Продажа | G10: 110 | H10: Центральный | J10: =E10*G10 -> 15840
A11: 1245 | B11: 45084 | C11: M15 | D11: 21 | E11: 129 | F11: Продажа | G11: 110 | H11: Центральный | J11: =E11*G11 -> 14190
A12: 1261 | B12: 45084 | C12: M18 | D12: 1 | E12: 128 | F12: Продажа | G12: 110 | H12: Центральный | J12: =E12*G12 -> 14080
A13: 1281 | B13: 45084 | C13: M18 | D13: 21 | E13: 123 | F13: Продажа | G13: 110 | H13: Центральный | J13: =E13*G13 -> 13530
... A373: 3430 | B373: 45091 | C373: M18 | D373: 10 | E373: 164 | F373: Продажа | G373: 600 | H373: Центральный | J373: =E373*G373 -> 98400
J374: =E374*G374 -> 0
J375: =E375*G375 -> 0
J376: =E376*G376 -> 0
J377: =E377*G377 -> 0
J378: =E378*G378 -> 0
J379: =E379*G379 -> 0
J380: =E380*G380 -> 0
J381: =E381*G381 -> 0
J382: =E382*G382 -> 0
J383: =E383*G383 -> 0
J384: =E384*G384 -> 0
J385: =E385*G385 -> 0
... J388: =E388*G388 -> 0

Sheet Движение товаров
A1: ID операции | B1: Дата | C1: ID магазина | D1: Артикул | E1: Количество упаковок, шт. | F1: Тип операции | G1: Цена товара | H1: Район
A2: 1 | B2: 45078 | C2: M1 | D2: 1 | E2: 200 | F2: Поступление | G2: =VLOOKUP(D2, Товар!A:F, 6,0) -> 110 | H2: =VLOOKUP(C2, Магазин!A:C, 2,0 ) -> Центральный
A3: 21 | B3: 45078 | C3: M1 | D3: 21 | E3: 200 | F3: Поступление | G3: =VLOOKUP(D3, Товар!A:F, 6,0) -> 110 | H3: =VLOOKUP(C3, Магазин!A:C, 2,0 ) -> Центральный
A4: 37 | B4: 45079 | C4: M5 | D4: 1 | E4: 200 | F4: Поступление | G4: =VLOOKUP(D4, Товар!A:F, 6,0) -> 110 | H4: =VLOOKUP(C4, Магазин!A:C, 2,0 ) -> Центральный
A5: 57 | B5: 45079 | C5: M5 | D5: 21 | E5: 200 | F5: Поступление | G5: =VLOOKUP(D5, Товар!A:F, 6,0) -> 110 | H5: =VLOOKUP(C5, Магазин!A:C, 2,0 ) -> Центральный
A6: 73 | B6: 45079 | C6: M6 | D6: 1 | E6: 200 | F6: Поступление | G6: =VLOOKUP(D6, Товар!A:F, 6,0) -> 110 | H6: =VLOOKUP(C6, Магазин!A:C, 2,0 ) -> Центральный
A7: 93 | B7: 45079 | C7: M6 | D7: 21 | E7: 200 | F7: Поступление | G7: =VLOOKUP(D7, Товар!A:F, 6,0) -> 110 | H7: =VLOOKUP(C7, Магазин!A:C, 2,0 ) -> Центральный
A8: 109 | B8: 45079 | C8: M10 | D8: 1 | E8: 200 | F8: Поступление | G8: =VLOOKUP(D8, Товар!A:F, 6,0) -> 110 | H8: =VLOOKUP(C8, Магазин!A:C, 2,0 ) -> Центральный
A9: 129 | B9: 45079 | C9: M10 | D9: 21 | E9: 200 | F9: Поступление | G9: =VLOOKUP(D9, Товар!A:F, 6,0) -> 110 | H9: =VLOOKUP(C9, Магазин!A:C, 2,0 ) -> Центральный
A10: 145 | B10: 45079 | C10: M15 | D10: 1 | E10: 200 | F10: Поступление | G10: =VLOOKUP(D10, Товар!A:F, 6,0) -> 110 | H10: =VLOOKUP(C10, Магазин!A:C, 2,0 ) -> Центральный
A11: 165 | B11: 45079 | C11: M15 | D11: 21 | E11: 200 | F11: Поступление | G11: =VLOOKUP(D11, Товар!A:F, 6,0) -> 110 | H11: =VLOOKUP(C11, Магазин!A:C, 2,0 ) -> Центральный
A12: 181 | B12: 45079 | C12: M18 | D12: 1 | E12: 200 | F12: Поступление | G12: =VLOOKUP(D12, Товар!A:F, 6,0) -> 110 | H12: =VLOOKUP(C12, Магазин!A:C, 2,0 ) -> Центральный
A13: 201 | B13: 45079 | C13: M18 | D13: 21 | E13: 200 | F13: Поступление | G13: =VLOOKUP(D13, Товар!A:F, 6,0) -> 110 | H13: =VLOOKUP(C13, Магазин!A:C, 2,0 ) -> Центральный
... A204: 3332 | B204: 45091 | C204: M6 | D204: 20 | E204: 176 | F204: Продажа | G204: =VLOOKUP(D204, Товар!A:F, 6,0) -> 120 | H204: =VLOOKUP(C204, Магазин!A:C, 2,0 ) -> Центральный
A205: 217 | B205: 45079 | C205: M2 | D205: 1 | E205: 300 | F205: Поступление | G205: =VLOOKUP(D205, Товар!A:F, 6,0) -> 110 | H205: =VLOOKUP(C205,Магазин!A:C, 2,0 ) -> Промышленный
A206: 218 | B206: 45079 | C206: M2 | D206: 2 | E206: 300 | F206: Поступление | G206: =VLOOKUP(D206, Товар!A:F, 6,0) -> 250 | H206: =VLOOKUP(C206,Магазин!A:C, 2,0 ) -> Промышленный
A207: 219 | B207: 45079 | C207: M2 | D207: 3 | E207: 300 | F207: Поступление | G207: =VLOOKUP(D207, Товар!A:F, 6,0) -> 300 | H207: =VLOOKUP(C207,Магазин!A:C, 2,0 ) -> Промышленный
A208: 224 | B208: 45079 | C208: M2 | D208: 8 | E208: 300 | F208: Поступление | G208: =VLOOKUP(D208, Товар!A:F, 6,0) -> 50 | H208: =VLOOKUP(C208,Магазин!A:C, 2,0 ) -> Промышленный
A209: 225 | B209: 45079 | C209: M2 | D209: 9 | E209: 300 | F209: Поступление | G209: =VLOOKUP(D209, Товар!A:F, 6,0) -> 90 | H209: =VLOOKUP(C209,Магазин!A:C, 2,0 ) -> Промышленный
A210: 226 | B210: 45079 | C210: M2 | D210: 10 | E210: 300 | F210: Поступление | G210: =VLOOKUP(D210, Товар!A:F, 6,0) -> 600 | H210: =VLOOKUP(C210,Магазин!A:C, 2,0 ) -> Промышленный
A211: 227 | B211: 45079 | C211: M2 | D211: 11 | E211: 300 | F211: Поступление | G211: =VLOOKUP(D211, Товар!A:F, 6,0) -> 100 | H211: =VLOOKUP(C211,Магазин!A:C, 2,0 ) -> Промышленный
A212: 228 | B212: 45079 | C212: M2 | D212: 12 | E212: 300 | F212: Поступление | G212: =VLOOKUP(D212, Товар!A:F, 6,0) -> 55 | H212: =VLOOKUP(C212,Магазин!A:C, 2,0 ) -> Промышленный
A213: 229 | B213: 45079 | C213: M2 | D213: 13 | E213: 300 | F213: Поступление | G213: =VLOOKUP(D213, Товар!A:F, 6,0) -> 85 | H213: =VLOOKUP(C213,Магазин!A:C, 2,0 ) -> Промышленный
A214: 230 | B214: 45079 | C214: M2 | D214: 14 | E214: 300 | F214: Поступление | G214: =VLOOKUP(D214, Товар!A:F, 6,0) -> 220 | H214: =VLOOKUP(C214,Магазин!A:C, 2,0 ) -> Промышленный
A215: 231 | B215: 45079 | C215: M2 | D215: 15 | E215: 300 | F215: Поступление | G215: =VLOOKUP(D215, Товар!A:F, 6,0) -> 300 | H215: =VLOOKUP(C215,Магазин!A:C, 2,0 ) -> Промышленный
A216: 232 | B216: 45079 | C216: M2 | D216: 16 | E216: 300 | F216: Поступление | G216: =VLOOKUP(D216, Товар!A:F, 6,0) -> 20 | H216: =VLOOKUP(C216,Магазин!A:C, 2,0 ) -> Промышленный
... A588: 648 | B588: 45079 | C588: M17 | D588: 36 | E588: 100 | F588: Поступление | G588: =VLOOKUP(D588, Товар!A:F, 6,0) -> 375 | H588: =VLOOKUP(C588,Магазин!A:C, 2,0 ) -> Заречный
A589: 3334 | B589: 45091 | C589: M6 | D589: 22 | E589: 146 | F589: Продажа | G589: =VLOOKUP(D589, Товар!A:F, 6,0) -> 120 | H589: =VLOOKUP(C589, Магазин!A:C, 2,0 ) -> Центральный
A590: 3365 | B590: 45091 | C590: M10 | D590: 17 | E590: 128 | F590: Продажа | G590: =VLOOKUP(D590, Товар!A:F, 6,0) -> 120 | H590: =VLOOKUP(C590, Магазин!A:C, 2,0 ) -> Центральный
A591: 3366 | B591: 45091 | C591: M10 | D591: 18 | E591: 191 | F591: Продажа | G591: =VLOOKUP(D591, Товар!A:F, 6,0) -> 120 | H591: =VLOOKUP(C591, Магазин!A:C, 2,0 ) -> Центральный
A592: 3368 | B592: 45091 | C592: M10 | D592: 20 | E592: 167 | F592: Продажа | G592: =VLOOKUP(D592, Товар!A:F, 6,0) -> 120 | H592: =VLOOKUP(C592, Магазин!A:C, 2,0 ) -> Центральный
A593: 3370 | B593: 45091 | C593: M10 | D593: 22 | E593: 105 | F593: Продажа | G593: =VLOOKUP(D593, Товар!A:F, 6,0) -> 120 | H593: =VLOOKUP(C593, Магазин!A:C, 2,0 ) -> Центральный
A594: 3401 | B594: 45091 | C594: M15 | D594: 17 | E594: 147 | F594: Продажа | G594: =VLOOKUP(D594, Товар!A:F, 6,0) -> 120 | H594: =VLOOKUP(C594, Магазин!A:C, 2,0 ) -> Центральный
A595: 3402 | B595: 45091 | C595: M15 | D595: 18 | E595: 169 | F595: Продажа | G595: =VLOOKUP(D595, Товар!A:F, 6,0) -> 120 | H595: =VLOOKUP(C595, Магазин!A:C, 2,0 ) -> Центральный
A596: 3404 | B596: 45091 | C596: M15 | D596: 20 | E596: 147 | F596: Продажа | G596: =VLOOKUP(D596, Товар!A:F, 6,0) -> 120 | H596: =VLOOKUP(C596, Магазин!A:C, 2,0 ) -> Центральный
A597: 3406 | B597: 45091 | C597: M15 | D597: 22 | E597: 129 | F597: Продажа | G597: =VLOOKUP(D597, Товар!A:F, 6,0) -> 120 | H597: =VLOOKUP(C597, Магазин!A:C, 2,0 ) -> Центральный
A598: 3437 | B598: 45091 | C598: M18 | D598: 17 | E598: 156 | F598: Продажа | G598: =VLOOKUP(D598, Товар!A:F, 6,0) -> 120 | H598: =VLOOKUP(C598, Магазин!A:C, 2,0 ) -> Центральный
A599: 3438 | B599: 45091 | C599: M18 | D599: 18 | E599: 144 | F599: Продажа | G599: =VLOOKUP(D599, Товар!A:F, 6,0) -> 120 | H599: =VLOOKUP(C599, Магазин!A:C, 2,0 ) -> Центральный
A600: 3440 | B600: 45091 | C600: M18 | D600: 20 | E600: 169 | F600: Продажа | G600: =VLOOKUP(D600, Товар!A:F, 6,0) -> 120 | H600: =VLOOKUP(C600, Магазин!A:C, 2,0 ) -> Центральный
... A742: 3990 | B742: 45091 | C742: M15 | D742: 42 | E742: 234 | F742: Продажа | G742: =VLOOKUP(D742, Товар!A:F, 6,0) -> 150 | H742: =VLOOKUP(C742, Магазин!A:C, 2,0 ) -> Центральный
...

Sheet Товар
A1: Артикул | B1: Отдел | C1: Наименование товара | D1: Ед_изм | E1: Количество в упаковке | F1: Цена за упаковку
A2: 1 | B2: Конфеты | C2: Батончик соевый | D2: грамм | E2: 250 | F2: 110
A3: 2 | B3: Конфеты | C3: Заяц шоколадный большой | D3: шт | E3: 1 | F3: 250
A4: 3 | B4: Конфеты | C4: Заяц шоколадный малый | D4: шт | E4: 6 | F4: 300
A5: 4 | B5: Конфеты | C5: Зефир в шоколаде | D5: грамм | E5: 250 | F5: 220
A6: 5 | B6: Конфеты | C6: Зефир ванильный | D6: грамм | E6: 800 | F6: 200
A7: 6 | B7: Конфеты | C7: Зефир воздушный | D7: грамм | E7: 500 | F7: 150
A8: 7 | B8: Конфеты | C8: Зефир лимонный | D8: грамм | E8: 1000 | F8: 250
A9: 8 | B9: Конфеты | C9: Карамель "Барбарис" | D9: грамм | E9: 250 | F9: 50
A10: 9 | B10: Конфеты | C10: Карамель "Взлетная" | D10: грамм | E10: 500 | F10: 90
A11: 10 | B11: Конфеты | C11: Карамель "Раковая шейка" | D11: грамм | E11: 1000 | F11: 600
A12: 11 | B12: Конфеты | C12: Карамель клубничная | D12: грамм | E12: 500 | F12: 100
A13: 12 | B13: Конфеты | C13: Карамель лимонная | D13: грамм | E13: 250 | F13: 55
... A61: 60 | B61: Печенье | C61: Пряники шоколадные | D61: грамм | E61: 500 | F61: 85

Sheet Магазин
A1: ID магазина | B1: Район | C1: Адрес
A2: M1 | B2: Центральный | C2: просп. Мира, 45
A3: M2 | B3: Промышленный | C3: ул. Металлургов, 12
A4: M3 | B4: Заречный | C4: Колхозная, 11
A5: M4 | B5: Промышленный | C5: Заводская, 22
A6: M5 | B6: Центральный | C6: ул. Гагарина, 17
A7: M6 | B7: Центральный | C7: просп. Мира, 10
A8: M7 | B8: Промышленный | C8: Заводская, 3
A9: M8 | B9: Промышленный | C9: ул. Сталеваров, 14
A10: M9 | B10: Заречный | C10: Прибрежная, 7
A11: M10 | B11: Центральный | C11: пл. Революции, 1
A12: M11 | B12: Заречный | C12: Луговая, 21
... A19: M18 | B19: Центральный | C19: Лермонтова, 9
